Workbook

Sheet CLIENTES
A1: ID CLIENTE | B1: NOMBRE ASEGURADO
A2: CLI-001 | B2: Juan Gómez
A3: CLI-002 | B3: Pedro Fernández
A4: CLI-003 | B4: Lucas Rodríguez
A5: CLI-004 | B5: Mateo López
A6: CLI-005 | B6: Santiago Martínez
A7: CLI-006 | B7: Nicolás González
A8: CLI-007 | B8: Martín Pérez
A9: CLI-008 | B9: Tomás Sánchez
A10: CLI-009 | B10: Facundo Romero
A11: CLI-010 | B11: Agustín Díaz
A12: CLI-011 | B12: Franco Álvarez
... A301: CLI-300 | B301: Lautaro Medina

Sheet LISTAS
A1: TIPO DE SEGURO | B1: PROVINCIA | C1: FORMA DE PAGO | D1: FORMA DE PAGO | E1: ESTADO | J1: PROVINCIA | K1: PROBABILIDAD | L1: ACUMULADA | N1: TIPO DE SINIESTRO | O1: PROBABILIDAD | P1: ACUMULADA
A2: Responsabilidad Civil | B2: Buenos Aires | C2: Auto | D2: Mensual | E2: Vigente | J2: Buenos Aires | K2: 0.25 | L2: 0 | N2: Colisión | O2: 0.45 | P2: 0
A3: Terceros Completo | B3: Córdoba | C3: SUV | D3: Trimestral | E3: Vencida | J3: Córdoba | K3: 0.15 | L3: 0.25 | N3: Robo | O3: 0.2 | P3: 0.45
A4: Todo Riesgo con Franquicia | B4: Santa Fe | C4: Pickup | D4: Semestral | E4: Cancelada | J4: Santa Fe | K4: 0.12 | L4: 0.4 | N4: Rotura de cristales | O4: 0.15 | P4: 0.65
A5: Todo Riesgo sin Franquicia | B5: Mendoza | C5: Utilitario | D5: Anual | E5: Pendiente | J5: Mendoza | K5: 0.1 | L5: 0.52 | N5: Incendio | O5: 0.08 | P5: 0.8
B6: Río Negro | J6: Río Negro | K6: 0.09 | L6: 0.62 | N6: Daños por granizo | O6: 0.12 | P6: 0.88
B7: Neuquén | J7: Neuquén | K7: 0.07 | L7: 0.71 | N7: TOTAL | O7: 1 | P7: 1
B8: Chubut | J8: Chubut | K8: 0.06 | L8: 0.78
B9: Entre Ríos | J9: Entre Ríos | K9: 0.06 | L9: 0.84
B10: Tucumán | J10: Tucumán | K10: 0.05 | L10: 0.9
B11: Salta | J11: Salta | K11: 0.05 | L11: 0.95
J12: TOTAL | K12: 1 | L12: 1
A14: TIPO DE SEGURO | B14: COLISIÓN | C14: ROBO | D14: ROTURA DE CRISTALES | E14: INCENDIO | F14: DAÑOS POR GRANIZO | G14: FRANQUICIA | H14: FACTOR | N14: GRAVEDAD | O14: PROBABILIDAD | P14: ACUMULADA | Q14: % MÍNIMO | R14: % MÁXIMO
A15: Responsabilidad Civil | B15: NO | C15: NO | D15: NO | E15: NO | F15: NO | G15: 0 | H15: 0.6 | N15: Leve | O15: 0.5 | P15: 0 | Q15: 0.01 | R15: 0.15
A16: Terceros Completo | B16: NO | C16: SÍ | D16: SÍ | E16: SÍ | F16: SÍ | G16: 0 | H16: 0.85 | N16: Moderado | O16: 0.3 | P16: 0.5 | Q16: 0.15 | R16: 0.4
A17: Todo Riesgo con Franquicia | B17: SÍ | C17: SÍ | D17: SÍ | E17: SÍ | F17: SÍ | G17: 0.1 | H17: 1.1 | N17: Grave | O17: 0.15 | P17: 0.8 | Q17: 0.4 | R17: 0.7
A18: Todo Riesgo sin Franquicia | B18: SÍ | C18: SÍ | D18: SÍ | E18: SÍ | F18: SÍ | G18: 0 | H18: 1.3 | N18: Muy grave | O18: 0.05 | P18: 0.95 | Q18: 0.7 | R18: 1
J19: SITUACIÓN | K19: MÍNIMO | L19: MÁXIMO | N19: TOTAL | O19: 1 | P19: 1
J20: Vigente | K20: 0.8 | L20: 1
J21: Vencida | K21: 0 | L21: 0
A22: TASA BASE | B22: 0.02
N25: FORMA DE PAGO | O25: PROBABILIDAD | P25: ACUMULADA
A26: FACTOR PROVINCIAS | D26: AÑO | E26: AUTO | F26: UTILITARIO | G26: SUV | H26: PICKUP | I26: ANTIGÜEDAD | J26: PROBABILIDAD | K26: ACUMULADA | N26: — | O26: — | P26: 0
A27: 1.2 | B27: Buenos Aires | D27: 2026 | E27: 25000000 | F27: 32000000 | G27: 40000000 | H27: 45000000 | I27: 0 | J27: =70%/6 -> 0.11666667 | K27: 0 | N27: Mensual | O27: 0.55 | P27: 0.55
A28: 1.15 | B28: Córdoba | D28: 2025 | E28: 23000000 | F28: 29440000 | G28: 36800000 | H28: 41400000 | I28: 1 | J28: =70%/6 -> 0.11666667 | K28: =J27+K27 -> 0.11666667 | N28: Trimestral | O28: 0.2 | P28: 0.75
A29: 1.15 | B29: Santa Fe | D29: 2024 | E29: 21045000 | F29: 26938000 | G29: 33672000 | H29: 37881000 | I29: 2 | J29: =70%/6 -> 0.11666667 | K29: =J28+K28 -> 0.23333333 | N29: Semestral | O29: 0.15 | P29: 0.9
A30: 1.05 | B30: Mendoza | D30: 2023 | E30: 19151000 | F30: 24513000 | G30: 30642000 | H30: 34472000 | I30: 3 | J30: =70%/6 -> 0.11666667 | K30: =J29+K29 -> 0.35 | N30: Anual | O30: 0.1 | P30: 1
A31: 0.95 | B31: Río Negro | D31: 2022 | E31: 17427000 | F31: 22307000 | G31: 27884000 | H31: 31369000 | I31: 4 | J31: =70%/6 -> 0.11666667 | K31: =J30+K30 -> 0.46666667
A32: 1.05 | B32: Neuquén | D32: 2021 | E32: 15859000 | F32: 20299000 | G32: 25374000 | H32: 28546000 | I32: 5 | J32: =70%/6 -> 0.11666667 | K32: =J31+K31 -> 0.58333333
A33: 0.9 | B33: Chubut | D33: 2020 | E33: 14432000 | F33: 18472000 | G33: 23091000 | H33: 25977000 | I33: 6 | J33: =20%/5 -> 0.04 | K33: =J32+K32 -> 0.7
A34: 1 | B34: Entre Ríos | D34: 2019 | E34: 13133000 | F34: 16810000 | G34: 21012000 | H34: 23639000 | I34: 7 | J34: =20%/5 -> 0.04 | K34: =J33+K33 -> 0.74
A35: 1.1 | B35: Tucumán | D35: 2018 | E35: 11951000 | F35: 15297000 | G35: 19121000 | H35: 21511000 | I35: 8 | J35: =20%/5 -> 0.04 | K35: =J34+K34 -> 0.78
A36: 0.95 | B36: Salta | D36: 2017 | E36: 10875000 | F36: 13920000 | G36: 17400000 | H36: 19575000 | I36: 9 | J36: =20%/5 -> 0.04 | K36: =J35+K35 -> 0.82
A37: FACTOR EDADES | D37: 2016 | E37: 9951000 | F37: 12737000 | G37: 15921000 | H37: 17912000 | I37: 10 | J37: =20%/5 -> 0.04 | K37: =J36+K36 -> 0.86
A38: 1.5 | B38: 18 | D38: 2015 | E38: 9155000 | F38: 11718000 | G38: 14648000 | H38: 16479000 | I38: 11 | J38: =10%/10 -> 0.01 | K38: =J37+K37 -> 0.9
A39: 1.35 | B39: 21 | D39: 2014 | E39: 8422000 | F39: 10781000 | G39: 13476000 | H39: 15160000 | I39: 12 | J39: =10%/10 -> 0.01 | K39: =J38+K38 -> 0.91
A40: 1.2 | B40: 25 | D40: 2013 | E40: 7791000 | F40: 9972000 | G40: 12465000 | H40: 14023000 | I40: 13 | J40: =10%/10 -> 0.01 | K40: =J39+K39 -> 0.92
A41: 1 | B41: 30 | D41: 2012 | E41: 7206000 | F41: 9224000 | G41: 11530000 | H41: 12972000 | I41: 14 | J41: =10%/10 -> 0.01 | K41: =J40+K40 -> 0.93
A42: 0.95 | B42: 40 | D42: 2011 | E42: 6702000 | F42: 8579000 | G42: 10723000 | H42: 12064000 | I42: 15 | J42: =10%/10 -> 0.01 | K42: =J41+K41 -> 0.94
A43: 1 | B43: 50 | D43: 2010 | E43: 6233000 | F43: 7978000 | G43: 9973000 | H43: 11219000 | I43: 16 | J43: =10%/10 -> 0.01 | K43: =J42+K42 -> 0.95
...

Sheet POLIZAS
A1: ID PÓLIZA | B1: ID CLIENTE | C1: NOMBRE ASEGURADO | D1: FECHA DE INICIO | E1: FECHA VTO | F1: TIPO DE SEGURO | G1: PROVINCIA | H1: EDAD ASEGURADO | I1: FECHA NACIMIENTO ASEGURADO | J1: TIPO DE VEHICULO | K1: AÑO DEL VEHICULO | L1: PRIMA MENSUAL | M1: TASA FINAL | N1: SUMA ASEGURADA | O1: FORMA DE PAGO | P1: ESTADO DE LA PÓLIZA
A2: POL-0001 | B2: CLI-019 | C2: =_xlfn.XLOOKUP(B2,CLIENTES!$A$2:$A$301,CLIENTES!$B$2:$B$301) -> Matías Suárez | D2: 45117 | E2: =EDATE(D2,12) -> 45483 | F2: Terceros Completo | G2: Córdoba | H2: 29 | I2: 35608 | J2: Auto | K2: 2025 | L2: =(N2*M2)/12 -> 44965 | M2: =LISTAS!$B$22*_xlfn.XLOOKUP(G2,LISTAS!$B$27:$B$36,LISTAS!$A$27:$A$36)*_xlfn.XLOOKUP(H2,LISTAS!$B$38:$B$47,LISTAS!$A$38:$A$47,,-1)*_xlfn.XLOOKUP(J2,LISTAS!$E$26:$H$26,LISTAS!$E$48:$H$48)*_xlfn.XLOOKUP(F2,LISTAS!$A$15:$A$18,LISTAS!$H$15:$H$18) -> 0.02346 | N2: {=_xlfn.XLOOKUP(K2,LISTAS!$D$27:$D$47,_xlfn.XLOOKUP(J2,LISTAS!$E$26:$H$26,LISTAS!$E$27:$H$47))} -> 23000000 | O2: Semestral | P2: =IF(TODAY()<D2,"Pendiente",IF(TODAY()>E2,"Vencida","Vigente")) -> Vencida
A3: POL-0002 | B3: CLI-028 | C3: =_xlfn.XLOOKUP(B3,CLIENTES!$A$2:$A$301,CLIENTES!$B$2:$B$301) -> Emiliano Rojas | D3: 44967 | E3: =EDATE(D3,12) -> 45332 | F3: Responsabilidad Civil | G3: Mendoza | H3: 70 | I3: 20405 | J3: Auto | K3: 2021 | L3: =(N3*M3)/12 -> 23312.73 | M3: =LISTAS!$B$22*_xlfn.XLOOKUP(G3,LISTAS!$B$27:$B$36,LISTAS!$A$27:$A$36)*_xlfn.XLOOKUP(H3,LISTAS!$B$38:$B$47,LISTAS!$A$38:$A$47,,-1)*_xlfn.XLOOKUP(J3,LISTAS!$E$26:$H$26,LISTAS!$E$48:$H$48)*_xlfn.XLOOKUP(F3,LISTAS!$A$15:$A$18,LISTAS!$H$15:$H$18) -> 0.01764 | N3: {=_xlfn.XLOOKUP(K3,LISTAS!$D$27:$D$47,_xlfn.XLOOKUP(J3,LISTAS!$E$26:$H$26,LISTAS!$E$27:$H$47))} -> 15859000 | O3: Mensual | P3: =IF(TODAY()<D3,"Pendiente",IF(TODAY()>E3,"Vencida","Vigente")) -> Vencida
A4: POL-0003 | B4: CLI-130 | C4: =_xlfn.XLOOKUP(B4,CLIENTES!$A$2:$A$301,CLIENTES!$B$2:$B$301) -> Lucía Navarro | D4: 46002 | E4: =EDATE(D4,12) -> 46367 | F4: Responsabilidad Civil | G4: Mendoza | H4: 79 | I4: 17140 | J4: Utilitario | K4: 2010 | L4: =(N4*M4)/12 -> 12753.83 | M4: =LISTAS!$B$22*_xlfn.XLOOKUP(G4,LISTAS!$B$27:$B$36,LISTAS!$A$27:$A$36)*_xlfn.XLOOKUP(H4,LISTAS!$B$38:$B$47,LISTAS!$A$38:$A$47,,-1)*_xlfn.XLOOKUP(J4,LISTAS!$E$26:$H$26,LISTAS!$E$48:$H$48)*_xlfn.XLOOKUP(F4,LISTAS!$A$15:$A$18,LISTAS!$H$15:$H$18) -> 0.0191835 | N4: {=_xlfn.XLOOKUP(K4,LISTAS!$D$27:$D$47,_xlfn.XLOOKUP(J4,LISTAS!$E$26:$H$26,LISTAS!$E$27:$H$47))} -> 7978000 | O4: Trimestral | P4: =IF(TODAY()<D4,"Pendiente",IF(TODAY()>E4,"Vencida","Vigente")) -> Vigente
A5: POL-0004 | B5: CLI-212 | C5: =_xlfn.XLOOKUP(B5,CLIENTES!$A$2:$A$301,CLIENTES!$B$2:$B$301) -> Rodrigo Navarro | D5: 45987 | E5: =EDATE(D5,12) -> 46352 | F5: Todo Riesgo sin Franquicia | G5: Neuquén | H5: 80 | I5: 16837 | J5: Auto | K5: 2020 | L5: =(N5*M5)/12 -> 47607.56 | M5: =LISTAS!$B$22*_xlfn.XLOOKUP(G5,LISTAS!$B$27:$B$36,LISTAS!$A$27:$A$36)*_xlfn.XLOOKUP(H5,LISTAS!$B$38:$B$47,LISTAS!$A$38:$A$47,,-1)*_xlfn.XLOOKUP(J5,LISTAS!$E$26:$H$26,LISTAS!$E$48:$H$48)*_xlfn.XLOOKUP(F5,LISTAS!$A$15:$A$18,LISTAS!$H$15:$H$18) -> 0.039585 | N5: {=_xlfn.XLOOKUP(K5,LISTAS!$D$27:$D$47,_xlfn.XLOOKUP(J5,LISTAS!$E$26:$H$26,LISTAS!$E$27:$H$47))} -> 14432000 | O5: Mensual | P5: =IF(TODAY()<D5,"Pendiente",IF(TODAY()>E5,"Vencida","Vigente")) -> Vigente
A6: POL-0005 | B6: CLI-061 | C6: =_xlfn.XLOOKUP(B6,CLIENTES!$A$2:$A$301,CLIENTES!$B$2:$B$301) -> Pablo Torres | D6: 44493 | E6: =EDATE(D6,12) -> 44858 | F6: Terceros Completo | G6: Neuquén | H6: 37 | I6: 32480 | J6: SUV | K6: 2013 | L6: =(N6*M6)/12 -> 20395.856 | M6: =LISTAS!$B$22*_xlfn.XLOOKUP(G6,LISTAS!$B$27:$B$36,LISTAS!$A$27:$A$36)*_xlfn.XLOOKUP(H6,LISTAS!$B$38:$B$47,LISTAS!$A$38:$A$47,,-1)*_xlfn.XLOOKUP(J6,LISTAS!$E$26:$H$26,LISTAS!$E$48:$H$48)*_xlfn.XLOOKUP(F6,LISTAS!$A$15:$A$18,LISTAS!$H$15:$H$18) -> 0.019635 | N6: {=_xlfn.XLOOKUP(K6,LISTAS!$D$27:$D$47,_xlfn.XLOOKUP(J6,LISTAS!$E$26:$H$26,LISTAS!$E$27:$H$47))} -> 12465000 | O6: Trimestral | P6: =IF(TODAY()<D6,"Pendiente",IF(TODAY()>E6,"Vencida","Vigente")) -> Vencida
A7: POL-0006 | B7: CLI-026 | C7: =_xlfn.XLOOKUP(B7,CLIENTES!$A$2:$A$301,CLIENTES!$B$2:$B$301) -> Mariano Ortiz | D7: 45850 | E7: =EDATE(D7,12) -> 46215 | F7: Todo Riesgo sin Franquicia | G7: Tucumán | H7: 75 | I7: 18711 | J7: Pickup | K7: 2020 | L7: =(N7*M7)/12 -> 103238.01 | M7: =LISTAS!$B$22*_xlfn.XLOOKUP(G7,LISTAS!$B$27:$B$36,LISTAS!$A$27:$A$36)*_xlfn.XLOOKUP(H7,LISTAS!$B$38:$B$47,LISTAS!$A$38:$A$47,,-1)*_xlfn.XLOOKUP(J7,LISTAS!$E$26:$H$26,LISTAS!$E$48:$H$48)*_xlfn.XLOOKUP(F7,LISTAS!$A$15:$A$18,LISTAS!$H$15:$H$18) -> 0.0476905 | N7: {=_xlfn.XLOOKUP(K7,LISTAS!$D$27:$D$47,_xlfn.XLOOKUP(J7,LISTAS!$E$26:$H$26,LISTAS!$E$27:$H$47))} -> 25977000 | O7: Trimestral | P7: =IF(TODAY()<D7,"Pendiente",IF(TODAY()>E7,"Vencida","Vigente")) -> Vencida
A8: POL-0007 | B8: CLI-208 | C8: =_xlfn.XLOOKUP(B8,CLIENTES!$A$2:$A$301,CLIENTES!$B$2:$B$301) -> Daniel Núñez | D8: 44520 | E8: =EDATE(D8,12) -> 44885 | F8: Terceros Completo | G8: Mendoza | H8: 37 | I8: 32560 | J8: Utilitario | K8: 2025 | L8: =(N8*M8)/12 -> 45981.6 | M8: =LISTAS!$B$22*_xlfn.XLOOKUP(G8,LISTAS!$B$27:$B$36,LISTAS!$A$27:$A$36)*_xlfn.XLOOKUP(H8,LISTAS!$B$38:$B$47,LISTAS!$A$38:$A$47,,-1)*_xlfn.XLOOKUP(J8,LISTAS!$E$26:$H$26,LISTAS!$E$48:$H$48)*_xlfn.XLOOKUP(F8,LISTAS!$A$15:$A$18,LISTAS!$H$15:$H$18) -> 0.0187425 | N8: {=_xlfn.XLOOKUP(K8,LISTAS!$D$27:$D$47,_xlfn.XLOOKUP(J8,LISTAS!$E$26:$H$26,LISTAS!$E$27:$H$47))} -> 29440000 | O8: Mensual | P8: =IF(TODAY()<D8,"Pendiente",IF(TODAY()>E8,"Vencida","Vigente")) -> Vencida
A9: POL-0008 | B9: CLI-195 | C9: =_xlfn.XLOOKUP(B9,CLIENTES!$A$2:$A$301,CLIENTES!$B$2:$B$301) -> Tomás Acosta | D9: 44778 | E9: =EDATE(D9,12) -> 45143 | F9: Responsabilidad Civil | G9: Río Negro | H9: 26 | I9: 36444 | J9: SUV | K9: 2025 | L9: =(N9*M9)/12 -> 46147.2 | M9: =LISTAS!$B$22*_xlfn.XLOOKUP(G9,LISTAS!$B$27:$B$36,LISTAS!$A$27:$A$36)*_xlfn.XLOOKUP(H9,LISTAS!$B$38:$B$47,LISTAS!$A$38:$A$47,,-1)*_xlfn.XLOOKUP(J9,LISTAS!$E$26:$H$26,LISTAS!$E$48:$H$48)*_xlfn.XLOOKUP(F9,LISTAS!$A$15:$A$18,LISTAS!$H$15:$H$18) -> 0.015048 | N9: {=_xlfn.XLOOKUP(K9,LISTAS!$D$27:$D$47,_xlfn.XLOOKUP(J9,LISTAS!$E$26:$H$26,LISTAS!$E$27:$H$47))} -> 36800000 | O9: Mensual | P9: =IF(TODAY()<D9,"Pendiente",IF(TODAY()>E9,"Vencida","Vigente")) -> Vencida
A10: POL-0009 | B10: CLI-136 | C10: =_xlfn.XLOOKUP(B10,CLIENTES!$A$2:$A$301,CLIENTES!$B$2:$B$301) -> Paula Mansilla | D10: 45890 | E10: =EDATE(D10,12) -> 46255 | F10: Todo Riesgo sin Franquicia | G10: Neuquén | H10: 79 | I10: 17129 | J10: Pickup | K10: 2024 | L10: =(N10*M10)/12 -> 143703.94 | M10: =LISTAS!$B$22*_xlfn.XLOOKUP(G10,LISTAS!$B$27:$B$36,LISTAS!$A$27:$A$36)*_xlfn.XLOOKUP(H10,LISTAS!$B$38:$B$47,LISTAS!$A$38:$A$47,,-1)*_xlfn.XLOOKUP(J10,LISTAS!$E$26:$H$26,LISTAS!$E$48:$H$48)*_xlfn.XLOOKUP(F10,LISTAS!$A$15:$A$18,LISTAS!$H$15:$H$18) -> 0.04552275 | N10: {=_xlfn.XLOOKUP(K10,LISTAS!$D$27:$D$47,_xlfn.XLOOKUP(J10,LISTAS!$E$26:$H$26,LISTAS!$E$27:$H$47))} -> 37881000 | O10: Mensual | P10: =IF(TODAY()<D10,"Pendiente",IF(TODAY()>E10,"Vencida","Vigente")) -> Vencida
A11: POL-0010 | B11: CLI-186 | C11: =_xlfn.XLOOKUP(B11,CLIENTES!$A$2:$A$301,CLIENTES!$B$2:$B$301) -> Mariana Peralta | D11: 46128 | E11: =EDATE(D11,12) -> 46493 | F11: Todo Riesgo con Franquicia | G11: Santa Fe | H11: 73 | I11: 19510 | J11: Auto | K11: 2023 | L11: =(N11*M11)/12 -> 56527.368 | M11: =LISTAS!$B$22*_xlfn.XLOOKUP(G11,LISTAS!$B$27:$B$36,LISTAS!$A$27:$A$36)*_xlfn.XLOOKUP(H11,LISTAS!$B$38:$B$47,LISTAS!$A$38:$A$47,,-1)*_xlfn.XLOOKUP(J11,LISTAS!$E$26:$H$26,LISTAS!$E$48:$H$48)*_xlfn.XLOOKUP(F11,LISTAS!$A$15:$A$18,LISTAS!$H$15:$H$18) -> 0.03542 | N11: {=_xlfn.XLOOKUP(K11,LISTAS!$D$27:$D$47,_xlfn.XLOOKUP(J11,LISTAS!$E$26:$H$26,LISTAS!$E$27:$H$47))} -> 19151000 | O11: Mensual | P11: =IF(TODAY()<D11,"Pendiente",IF(TODAY()>E11,"Vencida","Vigente")) -> Vigente
A12: POL-0011 | B12: CLI-291 | C12: =_xlfn.XLOOKUP(B12,CLIENTES!$A$2:$A$301,CLIENTES!$B$2:$B$301) -> Matías Flores | D12: 44633 | E12: =EDATE(D12,12) -> 44998 | F12: Todo Riesgo sin Franquicia | G12: Río Negro | H12: 40 | I12: 31554 | J12: Pickup | K12: 2021 | L12: =(N12*M12)/12 -> 64192.223 | M12: =LISTAS!$B$22*_xlfn.XLOOKUP(G12,LISTAS!$B$27:$B$36,LISTAS!$A$27:$A$36)*_xlfn.XLOOKUP(H12,LISTAS!$B$38:$B$47,LISTAS!$A$38:$A$47,,-1)*_xlfn.XLOOKUP(J12,LISTAS!$E$26:$H$26,LISTAS!$E$48:$H$48)*_xlfn.XLOOKUP(F12,LISTAS!$A$15:$A$18,LISTAS!$H$15:$H$18) -> 0.02698475 | N12: {=_xlfn.XLOOKUP(K12,LISTAS!$D$27:$D$47,_xlfn.XLOOKUP(J12,LISTAS!$E$26:$H$26,LISTAS!$E$27:$H$47))} -> 28546000 | O12: Semestral | P12: =IF(TODAY()<D12,"Pendiente",IF(TODAY()>E12,"Vencida","Vigente")) -> Vencida
A13: POL-0012 | B13: CLI-043 | C13: =_xlfn.XLOOKUP(B13,CLIENTES!$A$2:$A$301,CLIENTES!$B$2:$B$301) -> Daniela Quiroga | D13: 44798 | E13: =EDATE(D13,12) -> 45163 | F13: Todo Riesgo sin Franquicia | G13: Neuquén | H13: 44 | I13: 29965 | J13: Utilitario | K13: 2020 | L13: =(N13*M13)/12 -> 41918.741 | M13: =LISTAS!$B$22*_xlfn.XLOOKUP(G13,LISTAS!$B$27:$B$36,LISTAS!$A$27:$A$36)*_xlfn.XLOOKUP(H13,LISTAS!$B$38:$B$47,LISTAS!$A$38:$A$47,,-1)*_xlfn.XLOOKUP(J13,LISTAS!$E$26:$H$26,LISTAS!$E$48:$H$48)*_xlfn.XLOOKUP(F13,LISTAS!$A$15:$A$18,LISTAS!$H$15:$H$18) -> 0.02723175 | N13: {=_xlfn.XLOOKUP(K13,LISTAS!$D$27:$D$47,_xlfn.XLOOKUP(J13,LISTAS!$E$26:$H$26,LISTAS!$E$27:$H$47))} -> 18472000 | O13: Anual | P13: =IF(TODAY()<D13,"Pendiente",IF(TODAY()>E13,"Vencida","Vigente")) -> Vencida
... A1001: POL-1000 | B1001: CLI-028 | C1001: =_xlfn.XLOOKUP(B1001,CLIENTES!$A$2:$A$301,CLIENTES!$B$2:$B$301) -> Emiliano Rojas | D1001: 44681 | E1001: =EDATE(D1001,12) -> 45046 | F1001: Todo Riesgo sin Franquicia | G1001: Mendoza | H1001: 33 | I1001: 33938 | J1001: SUV | K1001: 2017 | L1001: =(N1001*M1001)/12 -> 43543.5 | M1001: =LISTAS!$B$22*_xlfn.XLOOKUP(G1001,LISTAS!$B$27:$B$36,LISTAS!$A$27:$A$36)*_xlfn.XLOOKUP(H1001,LISTAS!$B$38:$B$47,LISTAS!$A$38:$A$47,,-1)*_xlfn.XLOOKUP(J1001,LISTAS!$E$26:$H$26,LISTAS!$E$48:$H$48)*_xlfn.XLOOKUP(F1001,LISTAS!$A$15:$A$18,LISTAS!$H$15:$H$18) -> 0.03003 | N1001: {=_xlfn.XLOOKUP(K1001,LISTAS!$D$27:$D$47,_xlfn.XLOOKUP(J1001,LISTAS!$E$26:$H$26,LISTAS!$E$27:$H$47))} -> 17400000 | O1001: Mensual | P1001: =IF(TODAY()<D1001,"Pendiente",IF(TODAY()>E1001,"Vencida","Vigente")) -> Vencida

Sheet SINIESTROS
A1: ID SINIESTRO | B1: ID PÓLIZA | C1: FECHA DEL SINIESTRO | D1: TIPO DE SINIESTRO | E1: GRAVEDAD | F1: PROVINCIA | G1: TIPO DE SEGURO | H1: TIPO DE VEHICULO | I1: IMPORTE RECLAMADO | J1: IMPORTE PAGADO | K1: ESTADO PÓLIZA | L1: ESTADO | M1: MOTIVO | N1: DÍAS HASTA RESOLUCIÓN | O1: ¿FRAUDE SOSPECHADO?
A2: SIN-001 | B2: POL-0270 | C2: 46078 | D2: Colisión | E2: Leve | F2: Buenos Aires | G2: Todo Riesgo con Franquicia | H2: =_xlfn.XLOOKUP(SINIESTROS[[#This Row],[ID PÓLIZA]],POLIZAS[ID PÓLIZA],POLIZAS[TIPO DE VEHICULO]) -> Utilitario | I2: 735305.84 | J2: 0 | K2: Vencida | L2: Rechazado | M2: Cobertura vencida | N2: 25 | O2: No
A3: SIN-002 | B3: POL-0867 | C3: 46229 | D3: Colisión | E3: Moderado | F3: Chubut | G3: Todo Riesgo sin Franquicia | H3: =_xlfn.XLOOKUP(SINIESTROS[[#This Row],[ID PÓLIZA]],POLIZAS[ID PÓLIZA],POLIZAS[TIPO DE VEHICULO]) -> Auto | I3: 3329214.7 | J3: 0 | K3: Vigente | L3: Pendiente | M3: - | N3: 9 | O3: No
A4: SIN-003 | B4: POL-0757 | C4: 45397 | D4: Robo | E4: Leve | F4: Mendoza | G4: Todo Riesgo con Franquicia | H4: =_xlfn.XLOOKUP(SINIESTROS[[#This Row],[ID PÓLIZA]],POLIZAS[ID PÓLIZA],POLIZAS[TIPO DE VEHICULO]) -> Utilitario | I4: 1298631.1 | J4: 1189532.4 | K4: Vigente | L4: Pagado | M4: - | N4: 31 | O4: No
A5: SIN-004 | B5: POL-0116 | C5: 46074 | D5: Colisión | E5: Moderado | F5: Córdoba | G5: Terceros Completo | H5: =_xlfn.XLOOKUP(SINIESTROS[[#This Row],[ID PÓLIZA]],POLIZAS[ID PÓLIZA],POLIZAS[TIPO DE VEHICULO]) -> SUV | I5: 9036148.9 | J5: 0 | K5: Vigente | L5: Rechazado | M5: Cobertura inválida | N5: 16 | O5: No
A6: SIN-005 | B6: POL-0848 | C6: 45793 | D6: Rotura de cristales | E6: Leve | F6: Buenos Aires | G6: Todo Riesgo sin Franquicia | H6: =_xlfn.XLOOKUP(SINIESTROS[[#This Row],[ID PÓLIZA]],POLIZAS[ID PÓLIZA],POLIZAS[TIPO DE VEHICULO]) -> Pickup | I6: 2961047.3 | J6: 0 | K6: Vencida | L6: Rechazado | M6: Cobertura vencida | N6: 6 | O6: No
A7: SIN-006 | B7: POL-0707 | C7: 45848 | D7: Daños por granizo | E7: Grave | F7: Córdoba | G7: Responsabilidad Civil | H7: =_xlfn.XLOOKUP(SINIESTROS[[#This Row],[ID PÓLIZA]],POLIZAS[ID PÓLIZA],POLIZAS[TIPO DE VEHICULO]) -> SUV | I7: 10673572 | J7: 0 | K7: Vencida | L7: Rechazado | M7: Cobertura vencida | N7: 29 | O7: No
A8: SIN-007 | B8: POL-0878 | C8: 45829 | D8: Robo | E8: Leve | F8: Santa Fe | G8: Responsabilidad Civil | H8: =_xlfn.XLOOKUP(SINIESTROS[[#This Row],[ID PÓLIZA]],POLIZAS[ID PÓLIZA],POLIZAS[TIPO DE VEHICULO]) -> SUV | I8: 1646471.4 | J8: 0 | K8: Vencida | L8: Rechazado | M8: Cobertura vencida | N8: 19 | O8: No
A9: SIN-008 | B9: POL-0220 | C9: 46202 | D9: Colisión | E9: Grave | F9: Buenos Aires | G9: Terceros Completo | H9: =_xlfn.XLOOKUP(SINIESTROS[[#This Row],[ID PÓLIZA]],POLIZAS[ID PÓLIZA],POLIZAS[TIPO DE VEHICULO]) -> SUV | I9: 16488651 | J9: 0 | K9: Vencida | L9: Rechazado | M9: Cobertura vencida | N9: 17 | O9: No
A10: SIN-009 | B10: POL-0553 | C10: 44552 | D10: Rotura de cristales | E10: Leve | F10: Mendoza | G10: Todo Riesgo con Franquicia | H10: =_xlfn.XLOOKUP(SINIESTROS[[#This Row],[ID PÓLIZA]],POLIZAS[ID PÓLIZA],POLIZAS[TIPO DE VEHICULO]) -> SUV | I10: 3271001.6 | J10: 0 | K10: Vigente | L10: Rechazado | M10: - | N10: 18 | O10: No
A11: SIN-010 | B11: POL-0056 | C11: 45738 | D11: Incendio | E11: Leve | F11: Santa Fe | G11: Responsabilidad Civil | H11: =_xlfn.XLOOKUP(SINIESTROS[[#This Row],[ID PÓLIZA]],POLIZAS[ID PÓLIZA],POLIZAS[TIPO DE VEHICULO]) -> Auto | I11: 2547451.5 | J11: 0 | K11: Vencida | L11: Rechazado | M11: Cobertura vencida | N11: 14 | O11: No
A12: SIN-011 | B12: POL-0520 | C12: 46138 | D12: Incendio | E12: Grave | F12: Neuquén | G12: Responsabilidad Civil | H12: =_xlfn.XLOOKUP(SINIESTROS[[#This Row],[ID PÓLIZA]],POLIZAS[ID PÓLIZA],POLIZAS[TIPO DE VEHICULO]) -> Pickup | I12: 17713353 | J12: 0 | K12: Vencida | L12: Rechazado | M12: Cobertura vencida | N12: 26 | O12: No
A13: SIN-012 | B13: POL-0359 | C13: 44653 | D13: Colisión | E13: Moderado | F13: Mendoza | G13: Todo Riesgo con Franquicia | H13: =_xlfn.XLOOKUP(SINIESTROS[[#This Row],[ID PÓLIZA]],POLIZAS[ID PÓLIZA],POLIZAS[TIPO DE VEHICULO]) -> Utilitario | I13: 6278083.2 | J13: 5856553.6 | K13: Vigente | L13: Pagado | M13: - | N13: 42 | O13: No
... A301: SIN-300 | B301: POL-0160 | C301: 46227 | D301: Daños por granizo | E301: Leve | F301: Río Negro | G301: Responsabilidad Civil | H301: =_xlfn.XLOOKUP(SINIESTROS[[#This Row],[ID PÓLIZA]],POLIZAS[ID PÓLIZA],POLIZAS[TIPO DE VEHICULO]) -> Pickup | I301: 3936381.3 | J301: 0 | K301: Vigente | L301: Rechazado | M301: Cobertura inválida | N301: 11 | O301: No

Sheet CALCULOS
A1: TIPO DE VEHICULO | B1: CANTIDAD DE POLIZAS | C1: FRECUENCIA | D1: MONTO PAGADO TOTAL | E1: SEVERIDAD MEDIA | F1: PRIMA PURA | G1: PRIMA TOTAL | H1: LOSS RATIO (SINIESTRALIDAD) | J1: TIPO DE SINIESTRO | K1: CANTIDAD DE SINIESTROS | L1: FRECUENCIA RESPECTO CARTERA POLIZAS | M1: MONTO PAGADO TOTAL | N1: SEVERIDAD MEDIA | O1: COSTO ESPERADO POR POLIZA
A2: Auto | B2: =COUNTIFS(POLIZAS[TIPO DE VEHICULO],A2) -> 241 | C2: =COUNTIFS(SINIESTROS[TIPO DE VEHICULO],A2)/B2 -> 0.28215768 | D2: =SUMIFS(SINIESTROS[IMPORTE PAGADO],SINIESTROS[TIPO DE VEHICULO],A2) -> 67849593 | E2: =Tabla2[[#This Row],[MONTO PAGADO TOTAL]]/Tabla2[[#This Row],[CANTIDAD DE POLIZAS]] -> 281533.58 | F2: =Tabla2[[#This Row],[FRECUENCIA]]*Tabla2[[#This Row],[SEVERIDAD MEDIA]] -> 79436.862 | G2: =SUMIF(POLIZAS[TIPO DE VEHICULO], Tabla2[[#This Row],[TIPO DE VEHICULO]], POLIZAS[PRIMA MENSUAL]) * 12 -> 91087438 | H2: =(Tabla2[[#This Row],[MONTO PAGADO TOTAL]]) /Tabla2[[#This Row],[PRIMA TOTAL]] -> 0.7448842 | J2: Colisión | K2: =COUNTIFS(SINIESTROS[TIPO DE SINIESTRO],J2) -> 137 | L2: =K2/COUNTA(POLIZAS[ID PÓLIZA]) -> 0.137 | M2: =SUMIFS(SINIESTROS[IMPORTE PAGADO],SINIESTROS[TIPO DE SINIESTRO],J2) -> 1.6514875e+08 | N2: =M2/K2 -> 1205465.4 | O2: =M2/COUNTA(POLIZAS[ID PÓLIZA]) -> 165148.75
A3: SUV | B3: =COUNTIFS(POLIZAS[TIPO DE VEHICULO],A3) -> 267 | C3: =COUNTIFS(SINIESTROS[TIPO DE VEHICULO],A3)/B3 -> 0.3670412 | D3: =SUMIFS(SINIESTROS[IMPORTE PAGADO],SINIESTROS[TIPO DE VEHICULO],A3) -> 1.8322171e+08 | E3: =Tabla2[[#This Row],[MONTO PAGADO TOTAL]]/Tabla2[[#This Row],[CANTIDAD DE POLIZAS]] -> 686223.65 | F3: =Tabla2[[#This Row],[FRECUENCIA]]*Tabla2[[#This Row],[SEVERIDAD MEDIA]] -> 251872.35 | G3: =SUMIF(POLIZAS[TIPO DE VEHICULO], Tabla2[[#This Row],[TIPO DE VEHICULO]], POLIZAS[PRIMA MENSUAL]) * 12 -> 1.7520641e+08 | H3: =(Tabla2[[#This Row],[MONTO PAGADO TOTAL]]) /Tabla2[[#This Row],[PRIMA TOTAL]] -> 1.0457478 | J3: Robo | K3: =COUNTIFS(SINIESTROS[TIPO DE SINIESTRO],J3) -> 53 | L3: =K3/COUNTA(POLIZAS[ID PÓLIZA]) -> 0.053 | M3: =SUMIFS(SINIESTROS[IMPORTE PAGADO],SINIESTROS[TIPO DE SINIESTRO],J3) -> 1.1420372e+08 | N3: =M3/K3 -> 2154787.2 | O3: =M3/COUNTA(POLIZAS[ID PÓLIZA]) -> 114203.72
A4: Pickup | B4: =COUNTIFS(POLIZAS[TIPO DE VEHICULO],A4) -> 260 | C4: =COUNTIFS(SINIESTROS[TIPO DE VEHICULO],A4)/B4 -> 0.28846154 | D4: =SUMIFS(SINIESTROS[IMPORTE PAGADO],SINIESTROS[TIPO DE VEHICULO],A4) -> 1.6384617e+08 | E4: =Tabla2[[#This Row],[MONTO PAGADO TOTAL]]/Tabla2[[#This Row],[CANTIDAD DE POLIZAS]] -> 630177.57 | F4: =Tabla2[[#This Row],[FRECUENCIA]]*Tabla2[[#This Row],[SEVERIDAD MEDIA]] -> 181781.99 | G4: =SUMIF(POLIZAS[TIPO DE VEHICULO], Tabla2[[#This Row],[TIPO DE VEHICULO]], POLIZAS[PRIMA MENSUAL]) * 12 -> 2.1806318e+08 | H4: =(Tabla2[[#This Row],[MONTO PAGADO TOTAL]]) /Tabla2[[#This Row],[PRIMA TOTAL]] -> 0.75137016 | J4: Rotura de cristales | K4: =COUNTIFS(SINIESTROS[TIPO DE SINIESTRO],J4) -> 45 | L4: =K4/COUNTA(POLIZAS[ID PÓLIZA]) -> 0.045 | M4: =SUMIFS(SINIESTROS[IMPORTE PAGADO],SINIESTROS[TIPO DE SINIESTRO],J4) -> 85837368 | N4: =M4/K4 -> 1907497.1 | O4: =M4/COUNTA(POLIZAS[ID PÓLIZA]) -> 85837.368
A5: Utilitario | B5: =COUNTIFS(POLIZAS[TIPO DE VEHICULO],A5) -> 232 | C5: =COUNTIFS(SINIESTROS[TIPO DE VEHICULO],A5)/B5 -> 0.25431034 | D5: =SUMIFS(SINIESTROS[IMPORTE PAGADO],SINIESTROS[TIPO DE VEHICULO],A5) -> 51431515 | E5: =Tabla2[[#This Row],[MONTO PAGADO TOTAL]]/Tabla2[[#This Row],[CANTIDAD DE POLIZAS]] -> 221687.57 | F5: =Tabla2[[#This Row],[FRECUENCIA]]*Tabla2[[#This Row],[SEVERIDAD MEDIA]] -> 56377.441 | G5: =SUMIF(POLIZAS[TIPO DE VEHICULO], Tabla2[[#This Row],[TIPO DE VEHICULO]], POLIZAS[PRIMA MENSUAL]) * 12 -> 1.1859474e+08 | H5: =(Tabla2[[#This Row],[MONTO PAGADO TOTAL]]) /Tabla2[[#This Row],[PRIMA TOTAL]] -> 0.43367449 | J5: Incendio | K5: =COUNTIFS(SINIESTROS[TIPO DE SINIESTRO],J5) -> 22 | L5: =K5/COUNTA(POLIZAS[ID PÓLIZA]) -> 0.022 | M5: =SUMIFS(SINIESTROS[IMPORTE PAGADO],SINIESTROS[TIPO DE SINIESTRO],J5) -> 21614631 | N5: =M5/K5 -> 982483.24 | O5: =M5/COUNTA(POLIZAS[ID PÓLIZA]) -> 21614.631
J6: Daños por granizo | K6: =COUNTIFS(SINIESTROS[TIPO DE SINIESTRO],J6) -> 43 | L6: =K6/COUNTA(POLIZAS[ID PÓLIZA]) -> 0.043 | M6: =SUMIFS(SINIESTROS[IMPORTE PAGADO],SINIESTROS[TIPO DE SINIESTRO],J6) -> 79544518 | N6: =M6/K6 -> 1849872.5 | O6: =M6/COUNTA(POLIZAS[ID PÓLIZA]) -> 79544.518
A9: VEHICULO | B9: COLISIÓN | C9: ROBO | D9: ROTURA DE CRISTALES | E9: INCENDIO | F9: DAÑOS POR GRANIZO | G9: TOTAL VEHICULO
A10: Auto | B10: =SUMIFS(SINIESTROS[IMPORTE PAGADO], SINIESTROS[TIPO DE VEHICULO], $A10, SINIESTROS[TIPO DE SINIESTRO], B$9) -> 4431677.2 | C10: =SUMIFS(SINIESTROS[IMPORTE PAGADO], SINIESTROS[TIPO DE VEHICULO], $A10, SINIESTROS[TIPO DE SINIESTRO], C$9) -> 13764818 | D10: =SUMIFS(SINIESTROS[IMPORTE PAGADO], SINIESTROS[TIPO DE VEHICULO], $A10, SINIESTROS[TIPO DE SINIESTRO], D$9) -> 21755526 | E10: =SUMIFS(SINIESTROS[IMPORTE PAGADO], SINIESTROS[TIPO DE VEHICULO], $A10, SINIESTROS[TIPO DE SINIESTRO], E$9) -> 20405387 | F10: =SUMIFS(SINIESTROS[IMPORTE PAGADO], SINIESTROS[TIPO DE VEHICULO], $A10, SINIESTROS[TIPO DE SINIESTRO], F$9) -> 7492184.6 | G10: =SUM(Tabla5[[#This Row],[COLISIÓN]:[DAÑOS POR GRANIZO]]) -> 67849593
A11: SUV | B11: =SUMIFS(SINIESTROS[IMPORTE PAGADO], SINIESTROS[TIPO DE VEHICULO], $A11, SINIESTROS[TIPO DE SINIESTRO], B$9) -> 56352754 | C11: =SUMIFS(SINIESTROS[IMPORTE PAGADO], SINIESTROS[TIPO DE VEHICULO], $A11, SINIESTROS[TIPO DE SINIESTRO], C$9) -> 65878401 | D11: =SUMIFS(SINIESTROS[IMPORTE PAGADO], SINIESTROS[TIPO DE VEHICULO], $A11, SINIESTROS[TIPO DE SINIESTRO], D$9) -> 37456488 | E11: =SUMIFS(SINIESTROS[IMPORTE PAGADO], SINIESTROS[TIPO DE VEHICULO], $A11, SINIESTROS[TIPO DE SINIESTRO], E$9) -> 310451.94 | F11: =SUMIFS(SINIESTROS[IMPORTE PAGADO], SINIESTROS[TIPO DE VEHICULO], $A11, SINIESTROS[TIPO DE SINIESTRO], F$9) -> 23223618 | G11: =SUM(Tabla5[[#This Row],[COLISIÓN]:[DAÑOS POR GRANIZO]]) -> 1.8322171e+08
A12: Pickup | B12: =SUMIFS(SINIESTROS[IMPORTE PAGADO], SINIESTROS[TIPO DE VEHICULO], $A12, SINIESTROS[TIPO DE SINIESTRO], B$9) -> 79769604 | C12: =SUMIFS(SINIESTROS[IMPORTE PAGADO], SINIESTROS[TIPO DE VEHICULO], $A12, SINIESTROS[TIPO DE SINIESTRO], C$9) -> 28015226 | D12: =SUMIFS(SINIESTROS[IMPORTE PAGADO], SINIESTROS[TIPO DE VEHICULO], $A12, SINIESTROS[TIPO DE SINIESTRO], D$9) -> 13630071 | E12: =SUMIFS(SINIESTROS[IMPORTE PAGADO], SINIESTROS[TIPO DE VEHICULO], $A12, SINIESTROS[TIPO DE SINIESTRO], E$9) -> 898792.23 | F12: =SUMIFS(SINIESTROS[IMPORTE PAGADO], SINIESTROS[TIPO DE VEHICULO], $A12, SINIESTROS[TIPO DE SINIESTRO], F$9) -> 41532475 | G12: =SUM(Tabla5[[#This Row],[COLISIÓN]:[DAÑOS POR GRANIZO]]) -> 1.6384617e+08
A13: Utilitario | B13: =SUMIFS(SINIESTROS[IMPORTE PAGADO], SINIESTROS[TIPO DE VEHICULO], $A13, SINIESTROS[TIPO DE SINIESTRO], B$9) -> 24594718 | C13: =SUMIFS(SINIESTROS[IMPORTE PAGADO], SINIESTROS[TIPO DE VEHICULO], $A13, SINIESTROS[TIPO DE SINIESTRO], C$9) -> 6545274.5 | D13: =SUMIFS(SINIESTROS[IMPORTE PAGADO], SINIESTROS[TIPO DE VEHICULO], $A13, SINIESTROS[TIPO DE SINIESTRO], D$9) -> 12995282 | E13: =SUMIFS(SINIESTROS[IMPORTE PAGADO], SINIESTROS[TIPO DE VEHICULO], $A13, SINIESTROS[TIPO DE SINIESTRO], E$9) -> 0 | F13: =SUMIFS(SINIESTROS[IMPORTE PAGADO], SINIESTROS[TIPO DE VEHICULO], $A13, SINIESTROS[TIPO DE SINIESTRO], F$9) -> 7296240.2 | G13: =SUM(Tabla5[[#This Row],[COLISIÓN]:[DAÑOS POR GRANIZO]]) -> 51431515
A14: TOTAL SINIESTRO | B14: =SUM(B10:B13) -> 1.6514875e+08 | C14: =SUM(C10:C13) -> 1.1420372e+08 | D14: =SUM(D10:D13) -> 85837368 | E14: =SUM(E10:E13) -> 21614631 | F14: =SUM(F10:F13) -> 79544518 | G14: =SUM(Tabla5[[#This Row],[COLISIÓN]:[DAÑOS POR GRANIZO]]) -> 4.6634899e+08
